<robot
  name="hustac_pg_v3">
  <link
    name="base_link">
    <inertial>
      <origin
        xyz="-0.15238480173248 -4.93351760080252E-05 0.124894877385925"
        rpy="0 0 0" />
      <mass
        value="89.4624907016849" />
      <inertia
        ixx="1.43388345529093"
        ixy="0.000132975706657954"
        ixz="0.0514523207875984"
        iyy="2.61245349003453"
        iyz="0.000473477292610581"
        izz="2.01349439725166" />
    </inertial>
    <visual>
      <origin
        xyz="0 0 0"
        rpy="0 0 0" />
      <geometry>
        <mesh
          filename="package://hustac_pg_v3/meshes/base_link.STL" />
      </geometry>
      <material
        name="">
        <color
          rgba="1 1 1 1" />
      </material>
    </visual>
    <collision>
      <origin
        xyz="0 0 0"
        rpy="0 0 0" />
      <geometry>
        <mesh
          filename="package://hustac_pg_v3/meshes/base_link.STL" />
      </geometry>
    </collision>
  </link>
  <link
    name="torso_link">
    <inertial>
      <origin
        xyz="0.00079827642328939 3.01921383917825E-05 0.316114605643553"
        rpy="0 0 0" />
      <mass
        value="17.0454055093511" />
      <inertia
        ixx="0.619315965099835"
        ixy="-4.00339004677726E-05"
        ixz="-0.00436386396268781"
        iyy="0.570828514708695"
        iyz="-0.000158229659340948"
        izz="0.108622338127867" />
    </inertial>
    <visual>
      <origin
        xyz="0 0 0"
        rpy="0 0 0" />
      <geometry>
        <mesh
          filename="package://hustac_pg_v3/meshes/torso_link.STL" />
      </geometry>
      <material
        name="">
        <color
          rgba="1 1 1 1" />
      </material>
    </visual>
    <collision>
      <origin
        xyz="0 0 0"
        rpy="0 0 0" />
      <geometry>
        <mesh
          filename="package://hustac_pg_v3/meshes/torso_link.STL" />
      </geometry>
    </collision>
  </link>
  <joint
    name="torso_joint"
    type="prismatic">
    <origin
      xyz="-1.5832E-05 -1.5832E-05 0.5"
      rpy="-7.8886E-31 -2.4286E-16 -2.6984E-16" />
    <parent
      link="base_link" />
    <child
      link="torso_link" />
    <axis
      xyz="0 0 1" />
    <limit
      effort="0"
      velocity="0" />
  </joint>
  <link
    name="left_link1">
    <inertial>
      <origin
        xyz="4.74441436137951E-09 0.000860606471021985 -0.00379622825057979"
        rpy="0 0 0" />
      <mass
        value="0.282400129639665" />
      <inertia
        ixx="0.000253509602154742"
        ixy="-1.09826662940198E-11"
        ixz="1.85279386064996E-11"
        iyy="0.000155226372619024"
        iyz="-9.22617777124374E-07"
        izz="0.00023525341674752" />
    </inertial>
    <visual>
      <origin
        xyz="0 0 0"
        rpy="0 0 0" />
      <geometry>
        <mesh
          filename="package://hustac_pg_v3/meshes/left_link1.STL" />
      </geometry>
      <material
        name="">
        <color
          rgba="0.168627450980392 1 0.0274509803921569 1" />
      </material>
    </visual>
    <collision>
      <origin
        xyz="0 0 0"
        rpy="0 0 0" />
      <geometry>
        <mesh
          filename="package://hustac_pg_v3/meshes/left_link1.STL" />
      </geometry>
    </collision>
  </link>
  <joint
    name="left_joint1"
    type="continuous">
    <origin
      xyz="0 0.222 0.61"
      rpy="-3.473E-17 5.9674E-16 -3.1416" />
    <parent
      link="torso_link" />
    <child
      link="left_link1" />
    <axis
      xyz="0 0 1" />
  </joint>
  <link
    name="left_link2">
    <inertial>
      <origin
        xyz="9.45305167476818E-10 0.000860606505898143 -0.00379622536975684"
        rpy="0 0 0" />
      <mass
        value="0.2824001142096" />
      <inertia
        ixx="0.000253509580708817"
        ixy="-1.08641723538627E-11"
        ixz="5.26586097434057E-12"
        iyy="0.000155226373044821"
        iyz="-9.22617058430691E-07"
        izz="0.000235253423304767" />
    </inertial>
    <visual>
      <origin
        xyz="0 0 0"
        rpy="0 0 0" />
      <geometry>
        <mesh
          filename="package://hustac_pg_v3/meshes/left_link2.STL" />
      </geometry>
      <material
        name="">
        <color
          rgba="0.168627450980392 1 0.0274509803921569 1" />
      </material>
    </visual>
    <collision>
      <origin
        xyz="0 0 0"
        rpy="0 0 0" />
      <geometry>
        <mesh
          filename="package://hustac_pg_v3/meshes/left_link2.STL" />
      </geometry>
    </collision>
  </link>
  <joint
    name="left_joint2"
    type="continuous">
    <origin
      xyz="0 -0.085 0"
      rpy="1.7042 1.5708 0.13344" />
    <parent
      link="left_link1" />
    <child
      link="left_link2" />
    <axis
      xyz="0 0 1" />
  </joint>
  <link
    name="left_link3">
    <inertial>
      <origin
        xyz="2.09170347709176E-09 0.00037942163947207 -0.0993975720132856"
        rpy="0 0 0" />
      <mass
        value="0.640541692148901" />
      <inertia
        ixx="0.00726441985226313"
        ixy="-1.16273689308323E-11"
        ixz="-1.09560962278726E-10"
        iyy="0.00716601967778952"
        iyz="-2.41571265900033E-05"
        izz="0.000321135841128423" />
    </inertial>
    <visual>
      <origin
        xyz="0 0 0"
        rpy="0 0 0" />
      <geometry>
        <mesh
          filename="package://hustac_pg_v3/meshes/left_link3.STL" />
      </geometry>
      <material
        name="">
        <color
          rgba="0.792156862745098 0.819607843137255 0.933333333333333 1" />
      </material>
    </visual>
    <collision>
      <origin
        xyz="0 0 0"
        rpy="0 0 0" />
      <geometry>
        <mesh
          filename="package://hustac_pg_v3/meshes/left_link3.STL" />
      </geometry>
    </collision>
  </link>
  <joint
    name="left_joint3"
    type="continuous">
    <origin
      xyz="0 -0.35 0"
      rpy="-1.5708 9.3445E-17 3.1416" />
    <parent
      link="left_link2" />
    <child
      link="left_link3" />
    <axis
      xyz="0 0 1" />
  </joint>
  <link
    name="left_link4">
    <inertial>
      <origin
        xyz="5.23182497325081E-10 0.000987080498156996 -0.0110209547990487"
        rpy="0 0 0" />
      <mass
        value="0.188640665914286" />
      <inertia
        ixx="0.000135106424724665"
        ixy="-1.24512886620077E-11"
        ixz="4.47078440437611E-12"
        iyy="0.000108943726861082"
        iyz="-2.05214060471245E-06"
        izz="8.93151006462272E-05" />
    </inertial>
    <visual>
      <origin
        xyz="0 0 0"
        rpy="0 0 0" />
      <geometry>
        <mesh
          filename="package://hustac_pg_v3/meshes/left_link4.STL" />
      </geometry>
      <material
        name="">
        <color
          rgba="0.792156862745098 0.819607843137255 0.933333333333333 1" />
      </material>
    </visual>
    <collision>
      <origin
        xyz="0 0 0"
        rpy="0 0 0" />
      <geometry>
        <mesh
          filename="package://hustac_pg_v3/meshes/left_link4.STL" />
      </geometry>
    </collision>
  </link>
  <joint
    name="left_joint4"
    type="continuous">
    <origin
      xyz="0 -0.099 0"
      rpy="-1.5708 -1.1102E-16 -3.1416" />
    <parent
      link="left_link3" />
    <child
      link="left_link4" />
    <axis
      xyz="0 0 1" />
  </joint>
  <link
    name="left_link5">
    <inertial>
      <origin
        xyz="1.36848732346095E-09 0.000497540428185728 -0.078440352473969"
        rpy="0 0 0" />
      <mass
        value="0.188789060770594" />
      <inertia
        ixx="0.00171650030081302"
        ixy="-1.81891555994245E-12"
        ixz="-1.69828496417892E-11"
        iyy="0.00169655727215824"
        iyz="-7.36791722311758E-06"
        izz="5.19114920499587E-05" />
    </inertial>
    <visual>
      <origin
        xyz="0 0 0"
        rpy="0 0 0" />
      <geometry>
        <mesh
          filename="package://hustac_pg_v3/meshes/left_link5.STL" />
      </geometry>
      <material
        name="">
        <color
          rgba="0.792156862745098 0.819607843137255 0.933333333333333 1" />
      </material>
    </visual>
    <collision>
      <origin
        xyz="0 0 0"
        rpy="0 0 0" />
      <geometry>
        <mesh
          filename="package://hustac_pg_v3/meshes/left_link5.STL" />
      </geometry>
    </collision>
  </link>
  <joint
    name="left_joint5"
    type="continuous">
    <origin
      xyz="0 -0.3 0"
      rpy="-1.5708 -1.609E-16 3.1416" />
    <parent
      link="left_link4" />
    <child
      link="left_link5" />
    <axis
      xyz="0 0 1" />
  </joint>
  <link
    name="left_link6">
    <inertial>
      <origin
        xyz="6.11908634873259E-10 0.000997680391540134 -0.00297185603629835"
        rpy="0 0 0" />
      <mass
        value="0.0941485774984353" />
      <inertia
        ixx="4.39688594097792E-05"
        ixy="-1.75091815279349E-12"
        ixz="1.02575145125247E-12"
        iyy="2.40728118714626E-05"
        iyz="-2.79147001136473E-07"
        izz="4.03142529145276E-05" />
    </inertial>
    <visual>
      <origin
        xyz="0 0 0"
        rpy="0 0 0" />
      <geometry>
        <mesh
          filename="package://hustac_pg_v3/meshes/left_link6.STL" />
      </geometry>
      <material
        name="">
        <color
          rgba="0.792156862745098 0.819607843137255 0.933333333333333 1" />
      </material>
    </visual>
    <collision>
      <origin
        xyz="0 0 0"
        rpy="0 0 0" />
      <geometry>
        <mesh
          filename="package://hustac_pg_v3/meshes/left_link6.STL" />
      </geometry>
    </collision>
  </link>
  <joint
    name="left_joint6"
    type="continuous">
    <origin
      xyz="0 -0.064 0"
      rpy="-1.5708 6.9389E-18 -3.1416" />
    <parent
      link="left_link5" />
    <child
      link="left_link6" />
    <axis
      xyz="0 0 1" />
  </joint>
  <link
    name="left_link7">
    <inertial>
      <origin
        xyz="3.10255765523237E-10 0.00488175590325657 0.0094593306659026"
        rpy="0 0 0" />
      <mass
        value="0.0238610409992475" />
      <inertia
        ixx="6.6214330650804E-06"
        ixy="3.51067575959993E-14"
        ixz="1.50491756150449E-14"
        iyy="5.93593202992512E-06"
        iyz="-1.62955877142949E-06"
        izz="8.29159974096986E-06" />
    </inertial>
    <visual>
      <origin
        xyz="0 0 0"
        rpy="0 0 0" />
      <geometry>
        <mesh
          filename="package://hustac_pg_v3/meshes/left_link7.STL" />
      </geometry>
      <material
        name="">
        <color
          rgba="1 1 1 1" />
      </material>
    </visual>
    <collision>
      <origin
        xyz="0 0 0"
        rpy="0 0 0" />
      <geometry>
        <mesh
          filename="package://hustac_pg_v3/meshes/left_link7.STL" />
      </geometry>
    </collision>
  </link>
  <joint
    name="left_joint7"
    type="continuous">
    <origin
      xyz="0 -0.034 0"
      rpy="1.5708 1.5708 0" />
    <parent
      link="left_link6" />
    <child
      link="left_link7" />
    <axis
      xyz="0 0 1" />
  </joint>
  <link
    name="left_ee_link">
    <inertial>
      <origin
        xyz="-0.0104511249147865 0.0200422330307001 0.0047320266994747"
        rpy="0 0 0" />
      <mass
        value="0.00506893153791106" />
      <inertia
        ixx="2.42978795459253E-06"
        ixy="3.6419508303903E-07"
        ixz="2.13478750983576E-07"
        iyy="1.02186457282365E-06"
        iyz="-6.73507198403218E-07"
        izz="2.46533886484517E-06" />
    </inertial>
    <visual>
      <origin
        xyz="0 0 0"
        rpy="0 0 0" />
      <geometry>
        <mesh
          filename="package://hustac_pg_v3/meshes/left_ee_link.STL" />
      </geometry>
      <material
        name="">
        <color
          rgba="0.776470588235294 0.756862745098039 0.737254901960784 1" />
      </material>
    </visual>
    <collision>
      <origin
        xyz="0 0 0"
        rpy="0 0 0" />
      <geometry>
        <mesh
          filename="package://hustac_pg_v3/meshes/left_ee_link.STL" />
      </geometry>
    </collision>
  </link>
  <joint
    name="left_ee_joint"
    type="continuous">
    <origin
      xyz="-0.011 0.0105 0.022181"
      rpy="1.5708 6.4022E-19 2.2426E-16" />
    <parent
      link="left_link7" />
    <child
      link="left_ee_link" />
    <axis
      xyz="0 0 -1" />
  </joint>
  <link
    name="left_ee_link2">
    <inertial>
      <origin
        xyz="0.0098988779365487 0.020320662696838 0.0047320266994747"
        rpy="0 0 0" />
      <mass
        value="0.005068931537911" />
      <inertia
        ixx="2.44865465013533E-06"
        ixy="-3.25144959237628E-07"
        ixz="-1.94972377252117E-07"
        iyy="1.00299787728082E-06"
        iyz="-6.79095645348363E-07"
        izz="2.46533886484514E-06" />
    </inertial>
    <visual>
      <origin
        xyz="0 0 0"
        rpy="0 0 0" />
      <geometry>
        <mesh
          filename="package://hustac_pg_v3/meshes/left_ee_link2.STL" />
      </geometry>
      <material
        name="">
        <color
          rgba="0.776470588235294 0.756862745098039 0.737254901960784 1" />
      </material>
    </visual>
    <collision>
      <origin
        xyz="0 0 0"
        rpy="0 0 0" />
      <geometry>
        <mesh
          filename="package://hustac_pg_v3/meshes/left_ee_link2.STL" />
      </geometry>
    </collision>
  </link>
  <joint
    name="left_ee_joint2"
    type="continuous">
    <origin
      xyz="0.011 0.0105 0.022181"
      rpy="1.5708 6.4022E-19 2.2426E-16" />
    <parent
      link="left_link7" />
    <child
      link="left_ee_link2" />
    <axis
      xyz="0 0 -1" />
  </joint>
  <link
    name="right_link1">
    <inertial>
      <origin
        xyz="-0.000860606448409518 -2.87357232453545E-09 0.0362037717625117"
        rpy="0 0 0" />
      <mass
        value="0.282400129088101" />
      <inertia
        ixx="0.000155226372481429"
        ixy="1.28341065106155E-11"
        ixz="9.22617736839296E-07"
        iyy="0.000253509602809457"
        iyz="-6.97934423758907E-12"
        izz="0.000235253415531243" />
    </inertial>
    <visual>
      <origin
        xyz="0 0 0"
        rpy="0 0 0" />
      <geometry>
        <mesh
          filename="package://hustac_pg_v3/meshes/right_link1.STL" />
      </geometry>
      <material
        name="">
        <color
          rgba="0.168627450980392 1 0.0274509803921569 1" />
      </material>
    </visual>
    <collision>
      <origin
        xyz="0 0 0"
        rpy="0 0 0" />
      <geometry>
        <mesh
          filename="package://hustac_pg_v3/meshes/right_link1.STL" />
      </geometry>
    </collision>
  </link>
  <joint
    name="right_joint1"
    type="continuous">
    <origin
      xyz="0 -0.222 0.57"
      rpy="7.1471E-16 -1.449E-16 -1.5708" />
    <parent
      link="torso_link" />
    <child
      link="right_link1" />
    <axis
      xyz="0 0 1" />
  </joint>
  <link
    name="right_link2">
    <inertial>
      <origin
        xyz="-0.000860606505898087 9.45305056454515E-10 0.0362037746302432"
        rpy="0 0 0" />
      <mass
        value="0.2824001142096" />
      <inertia
        ixx="0.000155226373044821"
        ixy="1.08641723936732E-11"
        ixz="9.22617058430754E-07"
        iyy="0.000253509580708817"
        iyz="5.26586103113492E-12"
        izz="0.000235253423304767" />
    </inertial>
    <visual>
      <origin
        xyz="0 0 0"
        rpy="0 0 0" />
      <geometry>
        <mesh
          filename="package://hustac_pg_v3/meshes/right_link2.STL" />
      </geometry>
      <material
        name="">
        <color
          rgba="0.168627450980392 1 0.0274509803921569 1" />
      </material>
    </visual>
    <collision>
      <origin
        xyz="0 0 0"
        rpy="0 0 0" />
      <geometry>
        <mesh
          filename="package://hustac_pg_v3/meshes/right_link2.STL" />
      </geometry>
    </collision>
  </link>
  <joint
    name="right_joint2"
    type="continuous">
    <origin
      xyz="0.045 0 0.04"
      rpy="1.5708 3.4694E-16 1.5708" />
    <parent
      link="right_link1" />
    <child
      link="right_link2" />
    <axis
      xyz="0 0 1" />
  </joint>
  <link
    name="right_link3">
    <inertial>
      <origin
        xyz="-0.000379421629088439 -1.26689225776744E-09 0.205602427910165"
        rpy="0 0 0" />
      <mass
        value="0.640541691597337" />
      <inertia
        ixx="0.00716601967331769"
        ixy="1.24436265478109E-11"
        ixz="2.41571259156421E-05"
        iyy="0.00726441984857734"
        iyz="7.06008789773979E-11"
        izz="0.00032113583990587" />
    </inertial>
    <visual>
      <origin
        xyz="0 0 0"
        rpy="0 0 0" />
      <geometry>
        <mesh
          filename="package://hustac_pg_v3/meshes/right_link3.STL" />
      </geometry>
      <material
        name="">
        <color
          rgba="0.792156862745098 0.819607843137255 0.933333333333333 1" />
      </material>
    </visual>
    <collision>
      <origin
        xyz="0 0 0"
        rpy="0 0 0" />
      <geometry>
        <mesh
          filename="package://hustac_pg_v3/meshes/right_link3.STL" />
      </geometry>
    </collision>
  </link>
  <joint
    name="right_joint3"
    type="continuous">
    <origin
      xyz="0.045 0 0.04"
      rpy="0 -1.5708 0" />
    <parent
      link="right_link2" />
    <child
      link="right_link3" />
    <axis
      xyz="0 0 1" />
  </joint>
  <link
    name="right_link4">
    <inertial>
      <origin
        xyz="-0.000987080498156989 5.23182497325081E-10 0.0429790452009515"
        rpy="0 0 0" />
      <mass
        value="0.188640665914286" />
      <inertia
        ixx="0.000108943726861082"
        ixy="1.24512886751367E-11"
        ixz="2.0521406047124E-06"
        iyy="0.000135106424724665"
        iyz="4.47078447176444E-12"
        izz="8.93151006462272E-05" />
    </inertial>
    <visual>
      <origin
        xyz="0 0 0"
        rpy="0 0 0" />
      <geometry>
        <mesh
          filename="package://hustac_pg_v3/meshes/right_link4.STL" />
      </geometry>
      <material
        name="">
        <color
          rgba="0.792156862745098 0.819607843137255 0.933333333333333 1" />
      </material>
    </visual>
    <collision>
      <origin
        xyz="0 0 0"
        rpy="0 0 0" />
      <geometry>
        <mesh
          filename="package://hustac_pg_v3/meshes/right_link4.STL" />
      </geometry>
    </collision>
  </link>
  <joint
    name="right_joint4"
    type="continuous">
    <origin
      xyz="0.045 0 0.305"
      rpy="0 -1.5708 0" />
    <parent
      link="right_link3" />
    <child
      link="right_link4" />
    <axis
      xyz="0 0 1" />
  </joint>
  <link
    name="right_link5">
    <inertial>
      <origin
        xyz="-0.000497540423684217 -7.64793006702291E-10 0.186559647456351"
        rpy="0 0 0" />
      <mass
        value="0.188789060585377" />
      <inertia
        ixx="0.00169655727120642"
        ixy="2.01929499522621E-12"
        ixz="7.36791715343085E-06"
        iyy="0.0017165002999699"
        iyz="1.05846197099099E-11"
        izz="5.19114918573948E-05" />
    </inertial>
    <visual>
      <origin
        xyz="0 0 0"
        rpy="0 0 0" />
      <geometry>
        <mesh
          filename="package://hustac_pg_v3/meshes/right_link5.STL" />
      </geometry>
      <material
        name="">
        <color
          rgba="0.792156862745098 0.819607843137255 0.933333333333333 1" />
      </material>
    </visual>
    <collision>
      <origin
        xyz="0 0 0"
        rpy="0 0 0" />
      <geometry>
        <mesh
          filename="package://hustac_pg_v3/meshes/right_link5.STL" />
      </geometry>
    </collision>
  </link>
  <joint
    name="right_joint5"
    type="continuous">
    <origin
      xyz="0.035 0 0.054"
      rpy="0 -1.5708 0" />
    <parent
      link="right_link4" />
    <child
      link="right_link5" />
    <axis
      xyz="0 0 1" />
  </joint>
  <link
    name="right_link6">
    <inertial>
      <origin
        xyz="-0.00099768039154019 6.11908523850957E-10 0.0270281439637016"
        rpy="0 0 0" />
      <mass
        value="0.094148577498435" />
      <inertia
        ixx="2.40728118714625E-05"
        ixy="1.75091816867536E-12"
        ixz="2.79147001136419E-07"
        iyy="4.3968859409779E-05"
        iyz="1.02575140539852E-12"
        izz="4.03142529145275E-05" />
    </inertial>
    <visual>
      <origin
        xyz="0 0 0"
        rpy="0 0 0" />
      <geometry>
        <mesh
          filename="package://hustac_pg_v3/meshes/right_link6.STL" />
      </geometry>
      <material
        name="">
        <color
          rgba="0.792156862745098 0.819607843137255 0.933333333333333 1" />
      </material>
    </visual>
    <collision>
      <origin
        xyz="0 0 0"
        rpy="0 0 0" />
      <geometry>
        <mesh
          filename="package://hustac_pg_v3/meshes/right_link6.STL" />
      </geometry>
    </collision>
  </link>
  <joint
    name="right_joint6"
    type="continuous">
    <origin
      xyz="0.034 0 0.265"
      rpy="-2.1235 -1.5708 -1.0181" />
    <parent
      link="right_link5" />
    <child
      link="right_link6" />
    <axis
      xyz="0 0 1" />
  </joint>
  <link
    name="right_link7">
    <inertial>
      <origin
        xyz="-3.1025271240992E-10 -0.00488175590325302 0.0094593306659026"
        rpy="0 0 0" />
      <mass
        value="0.0238610409992475" />
      <inertia
        ixx="6.62143306508118E-06"
        ixy="3.5106417196243E-14"
        ixz="-1.50487913322843E-14"
        iyy="5.9359320299251E-06"
        iyz="1.62955877142993E-06"
        izz="8.29159974097066E-06" />
    </inertial>
    <visual>
      <origin
        xyz="0 0 0"
        rpy="0 0 0" />
      <geometry>
        <mesh
          filename="package://hustac_pg_v3/meshes/right_link7.STL" />
      </geometry>
      <material
        name="">
        <color
          rgba="1 1 1 1" />
      </material>
    </visual>
    <collision>
      <origin
        xyz="0 0 0"
        rpy="0 0 0" />
      <geometry>
        <mesh
          filename="package://hustac_pg_v3/meshes/right_link7.STL" />
      </geometry>
    </collision>
  </link>
  <joint
    name="right_joint7"
    type="continuous">
    <origin
      xyz="0.034 0 0.03"
      rpy="1.4901E-08 1.5708 0" />
    <parent
      link="right_link6" />
    <child
      link="right_link7" />
    <axis
      xyz="0 0 1" />
  </joint>
  <link
    name="right_ee_link">
    <inertial>
      <origin
        xyz="-0.00786989250531656 0.0211891953398733 0.00473202608235224"
        rpy="0 0 0" />
      <mass
        value="0.00506893153791104" />
      <inertia
        ixx="2.49802246746439E-06"
        ixy="1.78642502353209E-07"
        ixz="1.27813315060411E-07"
        iyy="9.53630059951783E-07"
        iyz="-6.94873283351523E-07"
        izz="2.46533886484515E-06" />
    </inertial>
    <visual>
      <origin
        xyz="0 0 0"
        rpy="0 0 0" />
      <geometry>
        <mesh
          filename="package://hustac_pg_v3/meshes/right_ee_link.STL" />
      </geometry>
      <material
        name="">
        <color
          rgba="0.776470588235294 0.756862745098039 0.737254901960784 1" />
      </material>
    </visual>
    <collision>
      <origin
        xyz="0 0 0"
        rpy="0 0 0" />
      <geometry>
        <mesh
          filename="package://hustac_pg_v3/meshes/right_ee_link.STL" />
      </geometry>
    </collision>
  </link>
  <joint
    name="right_ee_joint"
    type="continuous">
    <origin
      xyz="0.011 -0.0105 0.022181"
      rpy="1.5708 7.4751E-18 -3.1416" />
    <parent
      link="right_link7" />
    <child
      link="right_ee_link" />
    <axis
      xyz="0 0 -1" />
  </joint>
  <link
    name="right_ee_link2">
    <inertial>
      <origin
        xyz="0.00659519492785154 0.0216199102981847 0.00473202636787162"
        rpy="0 0 0" />
      <mass
        value="0.00506893153791103" />
      <inertia
        ixx="2.51377570664327E-06"
        ixy="-8.56492622315718E-08"
        ixz="-8.62419899790788E-08"
        iyy="9.37876820772901E-07"
        iyz="-7.012470624444E-07"
        izz="2.46533886484516E-06" />
    </inertial>
    <visual>
      <origin
        xyz="0 0 0"
        rpy="0 0 0" />
      <geometry>
        <mesh
          filename="package://hustac_pg_v3/meshes/right_ee_link2.STL" />
      </geometry>
      <material
        name="">
        <color
          rgba="0.776470588235294 0.756862745098039 0.737254901960784 1" />
      </material>
    </visual>
    <collision>
      <origin
        xyz="0 0 0"
        rpy="0 0 0" />
      <geometry>
        <mesh
          filename="package://hustac_pg_v3/meshes/right_ee_link2.STL" />
      </geometry>
    </collision>
  </link>
  <joint
    name="right_ee_joint2"
    type="continuous">
    <origin
      xyz="-0.011 -0.0105 0.022181"
      rpy="1.5708 7.4751E-18 -3.1416" />
    <parent
      link="right_link7" />
    <child
      link="right_ee_link2" />
    <axis
      xyz="0 0 -1" />
  </joint>
  <link
    name="gaze_link1">
    <inertial>
      <origin
        xyz="0.00332314338033088 -0.00166685318807747 0.0152159364388744"
        rpy="0 0 0" />
      <mass
        value="0.150566307832226" />
      <inertia
        ixx="0.000115144351223355"
        ixy="1.67570359368863E-06"
        ixz="-1.03958431832344E-05"
        iyy="0.000113564190859189"
        iyz="5.20649724762848E-06"
        izz="0.000139133815813377" />
    </inertial>
    <visual>
      <origin
        xyz="0 0 0"
        rpy="0 0 0" />
      <geometry>
        <mesh
          filename="package://hustac_pg_v3/meshes/gaze_link1.STL" />
      </geometry>
      <material
        name="">
        <color
          rgba="1 1 1 1" />
      </material>
    </visual>
    <collision>
      <origin
        xyz="0 0 0"
        rpy="0 0 0" />
      <geometry>
        <mesh
          filename="package://hustac_pg_v3/meshes/gaze_link1.STL" />
      </geometry>
    </collision>
  </link>
  <joint
    name="gaze_joint1"
    type="continuous">
    <origin
      xyz="0.128043357043904 0.00300000000000078 0.728"
      rpy="2.36658271566304E-30 2.4980018054066E-16 2.93111764559954E-15" />
    <parent
      link="torso_link" />
    <child
      link="gaze_link1" />
    <axis
      xyz="0 0 -1" />
  </joint>
  <link
    name="gaze_link2">
    <inertial>
      <origin
        xyz="-0.0933002369417906 -0.0315613902482235 -0.0210661375537419"
        rpy="0 0 0" />
      <mass
        value="0.137563261149672" />
      <inertia
        ixx="0.000246822046761975"
        ixy="-6.36584038385024E-05"
        ixz="1.92838091398628E-05"
        iyy="0.000348311526737285"
        iyz="1.12981590257425E-05"
        izz="0.000223382527067794" />
    </inertial>
    <visual>
      <origin
        xyz="0 0 0"
        rpy="0 0 0" />
      <geometry>
        <mesh
          filename="package://hustac_pg_v3/meshes/gaze_link2.STL" />
      </geometry>
      <material
        name="">
        <color
          rgba="1 1 1 1" />
      </material>
    </visual>
    <collision>
      <origin
        xyz="0 0 0"
        rpy="0 0 0" />
      <geometry>
        <mesh
          filename="package://hustac_pg_v3/meshes/gaze_link2.STL" />
      </geometry>
    </collision>
  </link>
  <joint
    name="gaze_joint2"
    type="continuous">
    <origin
      xyz="0.01 -0.031 0.0259999999999996"
      rpy="-1.69414531841237 1.57079631189374 2.99390185732041" />
    <parent
      link="gaze_link1" />
    <child
      link="gaze_link2" />
    <axis
      xyz="0 0 1" />
  </joint>
  <link
    name="movebase_link1">
    <inertial>
      <origin
        xyz="1.02755349557782E-05 -6.13131712068338E-09 -0.0238601812392363"
        rpy="0 0 0" />
      <mass
        value="1.21338763949041" />
      <inertia
        ixx="0.00568352810162066"
        ixy="-1.0842021724855E-19"
        ixz="5.73484408913423E-07"
        iyy="0.00568357790754469"
        iyz="-1.02724168633464E-15"
        izz="0.00215961172887464" />
    </inertial>
    <visual>
      <origin
        xyz="0 0 0"
        rpy="0 0 0" />
      <geometry>
        <mesh
          filename="package://hustac_pg_v3/meshes/movebase_link1.STL" />
      </geometry>
      <material
        name="">
        <color
          rgba="1 1 1 1" />
      </material>
    </visual>
    <collision>
      <origin
        xyz="0 0 0"
        rpy="0 0 0" />
      <geometry>
        <mesh
          filename="package://hustac_pg_v3/meshes/movebase_link1.STL" />
      </geometry>
    </collision>
  </link>
  <joint
    name="movebase_joint1"
    type="continuous">
    <origin
      xyz="0.25798 0.22848 -0.04"
      rpy="-1.5708 -1.0408E-16 0" />
    <parent
      link="base_link" />
    <child
      link="movebase_link1" />
    <axis
      xyz="0 0 -1" />
  </joint>
  <link
    name="movebase_link2">
    <inertial>
      <origin
        xyz="-1.03045985613281E-05 -1.19687882937924E-08 -0.0238601773090566"
        rpy="0 0 0" />
      <mass
        value="1.21338763949041" />
      <inertia
        ixx="0.00568352810268744"
        ixy="9.86623976961809E-17"
        ixz="-5.73484309891584E-07"
        iyy="0.00568357790861143"
        iyz="4.80842880986453E-13"
        izz="0.0021596117288746" />
    </inertial>
    <visual>
      <origin
        xyz="0 0 0"
        rpy="0 0 0" />
      <geometry>
        <mesh
          filename="package://hustac_pg_v3/meshes/movebase_link2.STL" />
      </geometry>
      <material
        name="">
        <color
          rgba="0.898039215686275 0.917647058823529 0.929411764705882 1" />
      </material>
    </visual>
    <collision>
      <origin
        xyz="0 0 0"
        rpy="0 0 0" />
      <geometry>
        <mesh
          filename="package://hustac_pg_v3/meshes/movebase_link2.STL" />
      </geometry>
    </collision>
  </link>
  <joint
    name="movebase_joint2"
    type="continuous">
    <origin
      xyz="-0.26202 0.22848 -0.04"
      rpy="-1.5708 -1.0408E-16 0" />
    <parent
      link="base_link" />
    <child
      link="movebase_link2" />
    <axis
      xyz="0 0 -1" />
  </joint>
  <link
    name="movebase_link3">
    <inertial>
      <origin
        xyz="1.0278061689184E-05 9.11185815688498E-09 -0.0238601748377876"
        rpy="0 0 0" />
      <mass
        value="1.21338763949041" />
      <inertia
        ixx="0.00568352809954946"
        ixy="-2.68014777038417E-16"
        ixz="5.73484002288182E-07"
        iyy="0.00568357790547329"
        iyz="1.10416715343139E-12"
        izz="0.00215961172887445" />
    </inertial>
    <visual>
      <origin
        xyz="0 0 0"
        rpy="0 0 0" />
      <geometry>
        <mesh
          filename="package://hustac_pg_v3/meshes/movebase_link3.STL" />
      </geometry>
      <material
        name="">
        <color
          rgba="0.898039215686275 0.917647058823529 0.929411764705882 1" />
      </material>
    </visual>
    <collision>
      <origin
        xyz="0 0 0"
        rpy="0 0 0" />
      <geometry>
        <mesh
          filename="package://hustac_pg_v3/meshes/movebase_link3.STL" />
      </geometry>
    </collision>
  </link>
  <joint
    name="movebase_joint3"
    type="continuous">
    <origin
      xyz="-0.26202 -0.23252 -0.04"
      rpy="-1.5708 1.8735E-16 3.1416" />
    <parent
      link="base_link" />
    <child
      link="movebase_link3" />
    <axis
      xyz="0 0 1" />
  </joint>
  <link
    name="movebase_link4">
    <inertial>
      <origin
        xyz="-1.02971285403097E-05 -3.72232578094156E-09 -0.0238601903592054"
        rpy="0 0 0" />
      <mass
        value="1.21338763949041" />
      <inertia
        ixx="0.00568352810178296"
        ixy="5.42101086242752E-19"
        ixz="-5.73484476032327E-07"
        iyy="0.00568357790770721"
        iyz="-7.86428967613288E-15"
        izz="0.00215961172887487" />
    </inertial>
    <visual>
      <origin
        xyz="0 0 0"
        rpy="0 0 0" />
      <geometry>
        <mesh
          filename="package://hustac_pg_v3/meshes/movebase_link4.STL" />
      </geometry>
      <material
        name="">
        <color
          rgba="1 1 1 1" />
      </material>
    </visual>
    <collision>
      <origin
        xyz="0 0 0"
        rpy="0 0 0" />
      <geometry>
        <mesh
          filename="package://hustac_pg_v3/meshes/movebase_link4.STL" />
      </geometry>
    </collision>
  </link>
  <joint
    name="movebase_joint4"
    type="continuous">
    <origin
      xyz="0.25798 -0.23252 -0.04"
      rpy="-1.5708 1.8735E-16 3.1416" />
    <parent
      link="base_link" />
    <child
      link="movebase_link4" />
    <axis
      xyz="0 0 1" />
  </joint>
  <link
    name="base_footprint" />
  <joint
    name="base_footprint_joint"
    type="fixed">
    <origin
      xyz="-1.5832309812891E-05 -1.58323099415103E-05 -0.11600000000001"
      rpy="-1.96455034355289E-16 -2.42861286636753E-16 -2.69836193741272E-16" />
    <parent
      link="base_link" />
    <child
      link="base_footprint" />
    <axis
      xyz="0 0 0" />
  </joint>
</robot>